Workbook

Sheet Métadonnées
A1: Nom du fichier xlsx | B1: T_8210
A2: Date de création du fichier | B2: 2025-10-17T09:15:24
A3: Onglet | B3: T_8210 | C3: 8.210 – Compte de patrimoine des ménages (S14)
A4: Source | B4: Comptes nationaux annuels (base 2020)
A6: COD_VAR | B6: LIB_VAR | C6: COD_MOD | D6: LIB_MOD
A7: FREQ | B7: Fréquence | C7: A | D7: Annuel
A8: TIME_PERIOD | B8: Période temporelle | C8: 1978 -> 2024 | D8: 1978 -> 2024
A9: GEO_DATE | B9: Millésime géographique
A10: GEO_SCOPE | B10: Périmètre géographique | C10: FE | D10: France entière
A11: ACCOUNTING_ENTRY | B11: Position de compte | C11: C | D11: Ressource ou crédit
A12: ACCOUNTING_ENTRY | B12: Position de compte | C12: D | D12: Emploi ou débit
A13: ACTIVITY | B13: Activité économique | C13: _T | D13: Total
A14: CONSOLIDATION | B14: Consolidation | C14: N | D14: Non consolidé
A15: COUNTERPART_AREA | B15: Zone de contrepartie | C15: W0 | D15: Monde
A16: COUNTERPART_SECTOR | B16: Secteur institutionnel de contrepartie | C16: S1 | D16: Économie totale
A17: EXPENDITURE | B17: Type de dépense de consommation | C17: _Z | D17: Total
A18: INSTR_ASSET | B18: Classe d'actifs passifs | C18: N111N | D18: Logements (net)
A19: INSTR_ASSET | B19: Classe d'actifs passifs | C19: N1121N | D19: Bâtiments non résidentiels (net)
A20: INSTR_ASSET | B20: Classe d'actifs passifs | C20: N2N | D20: Actifs non financiers non produits (net)
A21: INSTR_ASSET | B21: Classe d'actifs passifs | C21: F511 | D21: Actions cotées
... A69: VALUATION | B69: Valuation | C69: S | D69: Evaluation standard

Sheet Niveau
A1: 8.210 – Compte de patrimoine des ménages (S14)
A2: Unité : Milliards d'euros, en fin d'année
C4: 1978 | D4: 1979 | E4: 1980 | F4: 1981 | G4: 1982 | H4: 1983 | I4: 1984 | J4: 1985 | K4: 1986 | L4: 1987 | M4: 1988 | N4: 1989 | O4: 1990 | P4: 1991 | Q4: 1992 | R4: 1993 | S4: 1994 | T4: 1995 | U4: 1996 | V4: 1997 | W4: 1998 | X4: 1999 | Y4: 2000 | Z4: 2001 | AA4: 2002 | AB4: 2003 | AC4: 2004 | AD4: 2005 | AE4: 2006 | AF4: 2007 | AG4: 2008 | AH4: 2009 | AI4: 2010 | AJ4: 2011 | AK4: 2012 | AL4: 2013 | AM4: 2014 | AN4: 2015 | AO4: 2016 | AP4: 2017 | AQ4: 2018 | AR4: 2019 | AS4: 2020 | AT4: 2021 | AU4: 2022 | AV4: 2023 | AW4: 2024
A6: NN | B6: Total des actifs non financiers (net) | C6: 778.641 | D6: 899.909 | E6: 1026.051 | F6: 1154.598 | G6: 1274.534 | H6: 1399.243 | I6: 1466.728 | J6: 1532.327 | K6: 1620.772 | L6: 1716.474 | M6: 1848.238 | N6: 2005.584 | O6: 2145.773 | P6: 2171.116 | Q6: 2139.5 | R6: 2133.511 | S6: 2186.859 | T6: 2181.869 | U6: 2230.685 | V6: 2270.999 | W6: 2400.399 | X6: 2655.34 | Y6: 2929.644 | Z6: 3215.616 | AA6: 3623.73 | AB6: 4170.775 | AC6: 4897.774 | AD6: 5700.758 | AE6: 6328.283 | AF6: 6769.226 | AG6: 6489.052 | AH6: 6445.14 | AI6: 7012.899 | AJ6: 7286.289 | AK6: 7230.886 | AL6: 7185.659 | AM6: 7106.361 | AN6: 7167.711 | AO6: 7396.974 | AP6: 7725.384 | AQ6: 8059.674 | AR6: 8475.817 | AS6: 9028.041 | AT6: 9736.338 | AU6: 10235.023 | AV6: 9931.491 | AW6: 9867.778
A7: N1N | B7: Actifs non financiers produits (net) | C7: 486.393 | D7: 571.783 | E7: 664.528 | F7: 757.724 | G7: 860.371 | H7: 953.445 | I7: 1021.148 | J7: 1073.869 | K7: 1133.516 | L7: 1202.445 | M7: 1271.235 | N7: 1342.686 | O7: 1422.561 | P7: 1484.298 | Q7: 1523.948 | R7: 1560.813 | S7: 1597.478 | T7: 1646.091 | U7: 1704.501 | V7: 1757.932 | W7: 1807.379 | X7: 1871.167 | Y7: 1959.601 | Z7: 2069.731 | AA7: 2176.625 | AB7: 2299.668 | AC7: 2450.719 | AD7: 2611.205 | AE7: 2781.78 | AF7: 2959.98 | AG7: 3083.646 | AH7: 3166.008 | AI7: 3301.381 | AJ7: 3425.553 | AK7: 3501.676 | AL7: 3580.683 | AM7: 3653.291 | AN7: 3697.152 | AO7: 3784.357 | AP7: 3910.332 | AQ7: 4035.352 | AR7: 4146.477 | AS7: 4313.572 | AT7: 4701.545 | AU7: 5067.126 | AV7: 5206.065 | AW7: 5261.817
A8: N11N | B8: Actifs fixes par type d’actifs (net) | C8: 434.729 | D8: 512.626 | E8: 601.191 | F8: 695.424 | G8: 791.815 | H8: 873.774 | I8: 943.834 | J8: 1002.048 | K8: 1062.048 | L8: 1129.432 | M8: 1200.655 | N8: 1276.883 | O8: 1360.656 | P8: 1425.182 | Q8: 1466.453 | R8: 1502.232 | S8: 1539.694 | T8: 1587.608 | U8: 1645.286 | V8: 1700.239 | W8: 1748.024 | X8: 1803.467 | Y8: 1882.4 | Z8: 1978.018 | AA8: 2076.425 | AB8: 2198.93 | AC8: 2342.262 | AD8: 2487.58 | AE8: 2646.307 | AF8: 2823.968 | AG8: 2957.804 | AH8: 3038.231 | AI8: 3153.919 | AJ8: 3273.221 | AK8: 3354.002 | AL8: 3434.513 | AM8: 3504.772 | AN8: 3550.421 | AO8: 3636.054 | AP8: 3753.914 | AQ8: 3878.106 | AR8: 3991.675 | AS8: 4148.38 | AT8: 4500.558 | AU8: 4843.242 | AV8: 4986.725 | AW8: 5042.603
A9: N11KN | B9: Constructions (net) | C9: 411.214 | D9: 486.378 | E9: 571.114 | F9: 661.152 | G9: 752.762 | H9: 832.511 | I9: 900.946 | J9: 957.791 | K9: 1017.179 | L9: 1083.637 | M9: 1151.866 | N9: 1225.126 | O9: 1307.552 | P9: 1372.637 | Q9: 1415.647 | R9: 1453.348 | S9: 1491.495 | T9: 1540.829 | U9: 1599.979 | V9: 1655.439 | W9: 1703.537 | X9: 1759.329 | Y9: 1837.827 | Z9: 1933.9 | AA9: 2032.861 | AB9: 2155.541 | AC9: 2299.161 | AD9: 2444.805 | AE9: 2604.025 | AF9: 2781.737 | AG9: 2916.439 | AH9: 2997.704 | AI9: 3114.717 | AJ9: 3234.321 | AK9: 3315.185 | AL9: 3396.072 | AM9: 3467.257 | AN9: 3513.96 | AO9: 3600.314 | AP9: 3718.184 | AQ9: 3842.055 | AR9: 3954.577 | AS9: 4110.54 | AT9: 4461.275 | AU9: 4802.204 | AV9: 4945.131 | AW9: 5001.149
A10: N111N | B10: Logements (net) | C10: 366.873 | D10: 434.796 | E10: 511.398 | F10: 593.579 | G10: 677.924 | H10: 752.323 | I10: 817.121 | J10: 871.811 | K10: 928.451 | L10: 991.136 | M10: 1055.23 | N10: 1124.882 | O10: 1205.24 | P10: 1270.27 | Q10: 1314.513 | R10: 1352.529 | S10: 1389.948 | T10: 1438.619 | U10: 1496.424 | V10: 1549.9 | W10: 1595.614 | X10: 1647.497 | Y10: 1723.53 | Z10: 1818.4 | AA10: 1914.747 | AB10: 2034.21 | AC10: 2174.815 | AD10: 2317.159 | AE10: 2472.589 | AF10: 2644.971 | AG10: 2776.254 | AH10: 2855.334 | AI10: 2967.187 | AJ10: 3082.974 | AK10: 3163.058 | AL10: 3245.254 | AM10: 3319.9 | AN10: 3369.604 | AO10: 3454.529 | AP10: 3568.328 | AQ10: 3687.858 | AR10: 3797.345 | AS10: 3948.081 | AT10: 4284.832 | AU10: 4613.448 | AV10: 4752.687 | AW10: 4807.411
A11: N112N | B11: Autres bâtiments et ouvrages de génie civil (net) | C11: 44.341 | D11: 51.582 | E11: 59.716 | F11: 67.572 | G11: 74.839 | H11: 80.188 | I11: 83.825 | J11: 85.98 | K11: 88.728 | L11: 92.501 | M11: 96.636 | N11: 100.244 | O11: 102.313 | P11: 102.368 | Q11: 101.133 | R11: 100.819 | S11: 101.546 | T11: 102.21 | U11: 103.555 | V11: 105.539 | W11: 107.922 | X11: 111.832 | Y11: 114.298 | Z11: 115.499 | AA11: 118.113 | AB11: 121.331 | AC11: 124.347 | AD11: 127.646 | AE11: 131.435 | AF11: 136.766 | AG11: 140.184 | AH11: 142.37 | AI11: 147.53 | AJ11: 151.347 | AK11: 152.127 | AL11: 150.818 | AM11: 147.357 | AN11: 144.356 | AO11: 145.785 | AP11: 149.856 | AQ11: 154.197 | AR11: 157.232 | AS11: 162.459 | AT11: 176.444 | AU11: 188.756 | AV11: 192.444 | AW11: 193.738
A12: N1121N | B12: Bâtiments non résidentiels (net) | C12: 20.119 | D12: 22.581 | E12: 25.415 | F12: 28.102 | G12: 30.458 | H12: 32.086 | I12: 33.223 | J12: 33.504 | K12: 33.729 | L12: 34.274 | M12: 34.752 | N12: 35.318 | O12: 35.758 | P12: 35.838 | Q12: 35.482 | R12: 34.863 | S12: 34.275 | T12: 33.796 | U12: 33.331 | V12: 33.195 | W12: 33.199 | X12: 34.054 | Y12: 34.928 | Z12: 35.124 | AA12: 35.209 | AB12: 35.499 | AC12: 35.846 | AD12: 36.053 | AE12: 36.319 | AF12: 37.016 | AG12: 37.629 | AH12: 37.224 | AI12: 37 | AJ12: 36.985 | AK12: 36.538 | AL12: 35.82 | AM12: 35.18 | AN12: 34.785 | AO12: 35.089 | AP12: 35.828 | AQ12: 37.011 | AR12: 38.332 | AS12: 40.212 | AT12: 43.232 | AU12: 45.595 | AV12: 46.162 | AW12: 45.917
A13: N1122N | B13: Autres ouvrages de génie civil (net) | C13: 24.223 | D13: 29.001 | E13: 34.301 | F13: 39.471 | G13: 44.381 | H13: 48.103 | I13: 50.603 | J13: 52.476 | K13: 54.999 | L13: 58.227 | M13: 61.885 | N13: 64.926 | O13: 66.555 | P13: 66.529 | Q13: 65.651 | R13: 65.956 | S13: 67.271 | T13: 68.414 | U13: 70.224 | V13: 72.344 | W13: 74.723 | X13: 77.778 | Y13: 79.37 | Z13: 80.376 | AA13: 82.904 | AB13: 85.832 | AC13: 88.5 | AD13: 91.593 | AE13: 95.116 | AF13: 99.749 | AG13: 102.555 | AH13: 105.146 | AI13: 110.53 | AJ13: 114.362 | AK13: 115.59 | AL13: 114.997 | AM13: 112.177 | AN13: 109.571 | AO13: 110.697 | AP13: 114.027 | AQ13: 117.186 | AR13: 118.901 | AS13: 122.246 | AT13: 133.212 | AU13: 143.161 | AV13: 146.281 | AW13: 147.821
A14: N113N | B14: Machines et équipements (net) | C14: 12.78 | D14: 14.78 | E14: 17.515 | F14: 20.476 | G14: 22.932 | H14: 24.353 | I14: 25.496 | J14: 26.402 | K14: 27.388 | L14: 28.462 | M14: 29.862 | N14: 31.749 | O14: 33.347 | P14: 33.693 | Q14: 32.601 | R14: 31.396 | S14: 30.982 | T14: 30.982 | U14: 30.786 | V14: 30.404 | W14: 30.261 | X14: 30.705 | Y14: 31.322 | Z14: 31.048 | AA14: 30.632 | AB14: 30.646 | AC14: 30.852 | AD14: 30.883 | AE14: 30.612 | AF14: 30.534 | AG14: 30.449 | AH14: 29.807 | AI14: 28.881 | AJ14: 28.814 | AK14: 28.946 | AL14: 28.678 | AM14: 27.988 | AN14: 27.185 | AO14: 26.624 | AP14: 26.781 | AQ14: 27.127 | AR14: 27.741 | AS14: 28.527 | AT14: 29.582 | AU14: 30.295 | AV14: 30.801 | AW14: 29.8
A15: N1131N | B15: Matériels de transport (net) | C15: 1.443 | D15: 1.626 | E15: 1.85 | F15: 2.063 | G15: 2.28 | H15: 2.407 | I15: 2.49 | J15: 2.617 | K15: 2.785 | L15: 2.94 | M15: 3.132 | N15: 3.423 | O15: 3.623 | P15: 3.535 | Q15: 3.307 | R15: 3.12 | S15: 3.123 | T15: 3.197 | U15: 3.02 | V15: 2.847 | W15: 2.85 | X15: 2.867 | Y15: 3.023 | Z15: 3.178 | AA15: 3.35 | AB15: 3.731 | AC15: 4.053 | AD15: 4.259 | AE15: 4.434 | AF15: 4.619 | AG15: 4.391 | AH15: 4.077 | AI15: 3.828 | AJ15: 3.764 | AK15: 3.599 | AL15: 3.427 | AM15: 3.356 | AN15: 3.278 | AO15: 3.217 | AP15: 3.342 | AQ15: 3.417 | AR15: 3.669 | AS15: 3.883 | AT15: 4.187 | AU15: 3.913 | AV15: 3.726 | AW15: 3.532
A16: N1132N | B16: Équipements TIC (net) | C16: 0.158 | D16: 0.185 | E16: 0.229 | F16: 0.267 | G16: 0.311 | H16: 0.34 | I16: 0.388 | J16: 0.443 | K16: 0.507 | L16: 0.564 | M16: 0.628 | N16: 0.654 | O16: 0.668 | P16: 0.649 | Q16: 0.626 | R16: 0.608 | S16: 0.606 | T16: 0.592 | U16: 0.564 | V16: 0.54 | W16: 0.519 | X16: 0.529 | Y16: 0.504 | Z16: 0.45 | AA16: 0.404 | AB16: 0.399 | AC16: 0.39 | AD16: 0.385 | AE16: 0.364 | AF16: 0.321 | AG16: 0.297 | AH16: 0.268 | AI16: 0.266 | AJ16: 0.269 | AK16: 0.27 | AL16: 0.272 | AM16: 0.283 | AN16: 0.296 | AO16: 0.345 | AP16: 0.371 | AQ16: 0.41 | AR16: 0.409 | AS16: 0.433 | AT16: 0.45 | AU16: 0.43 | AV16: 0.404 | AW16: 0.391
A17: N1139N | B17: Autres machines et équipements (net) | C17: 11.179 | D17: 12.969 | E17: 15.436 | F17: 18.146 | G17: 20.341 | H17: 21.606 | I17: 22.618 | J17: 23.343 | K17: 24.096 | L17: 24.959 | M17: 26.102 | N17: 27.672 | O17: 29.056 | P17: 29.51 | Q17: 28.668 | R17: 27.668 | S17: 27.253 | T17: 27.193 | U17: 27.203 | V17: 27.017 | W17: 26.891 | X17: 27.309 | Y17: 27.795 | Z17: 27.42 | AA17: 26.878 | AB17: 26.517 | AC17: 26.408 | AD17: 26.239 | AE17: 25.814 | AF17: 25.593 | AG17: 25.762 | AH17: 25.462 | AI17: 24.787 | AJ17: 24.781 | AK17: 25.077 | AL17: 24.979 | AM17: 24.349 | AN17: 23.611 | AO17: 23.062 | AP17: 23.068 | AQ17: 23.3 | AR17: 23.663 | AS17: 24.211 | AT17: 24.945 | AU17: 25.953 | AV17: 26.671 | AW17: 25.877
A18: N114N | B18: Systèmes d’armes (net)
A19: N115N | B19: Ressources biologiques cultivées (net) | C19: 9.542 | D19: 10.139 | E19: 11.057 | F19: 12.106 | G19: 14.289 | H19: 14.986 | I19: 15.377 | J19: 15.76 | K19: 15.262 | L19: 15.001 | M19: 16.478 | N19: 17.401 | O19: 17.011 | P19: 16.068 | Q19: 15.428 | R19: 14.768 | S19: 14.461 | T19: 13.004 | U19: 11.747 | V19: 11.637 | W19: 11.434 | X19: 10.552 | Y19: 10.217 | Z19: 9.891 | AA19: 9.746 | AB19: 9.559 | AC19: 9.008 | AD19: 8.58 | AE19: 8.301 | AF19: 8.207 | AG19: 7.434 | AH19: 7.432 | AI19: 7.158 | AJ19: 6.954 | AK19: 6.704 | AL19: 6.591 | AM19: 6.357 | AN19: 6.108 | AO19: 5.919 | AP19: 5.653 | AQ19: 5.449 | AR19: 5.679 | AS19: 5.425 | AT19: 5.229 | AU19: 5.614 | AV19: 4.99 | AW19: 5.215
A20: N117N | B20: Droits de propriété intellectuelle (net) | C20: 1.193 | D20: 1.33 | E20: 1.504 | F20: 1.69 | G20: 1.832 | H20: 1.924 | I20: 2.015 | J20: 2.095 | K20: 2.218 | L20: 2.332 | M20: 2.449 | N20: 2.607 | O20: 2.746 | P20: 2.784 | Q20: 2.777 | R20: 2.719 | S20: 2.757 | T20: 2.792 | U20: 2.774 | V20: 2.759 | W20: 2.793 | X20: 2.882 | Y20: 3.034 | Z20: 3.179 | AA20: 3.186 | AB20: 3.184 | AC20: 3.241 | AD20: 3.312 | AE20: 3.369 | AF20: 3.491 | AG20: 3.482 | AH20: 3.287 | AI20: 3.164 | AJ20: 3.132 | AK20: 3.167 | AL20: 3.173 | AM20: 3.171 | AN20: 3.169 | AO20: 3.197 | AP20: 3.296 | AQ20: 3.474 | AR20: 3.678 | AS20: 3.888 | AT20: 4.472 | AU20: 5.129 | AV20: 5.803 | AW20: 6.439
A21: N1171N | B21: Recherche et développement (net) | C21: 0.889 | D21: 0.967 | E21: 1.087 | F21: 1.232 | G21: 1.348 | H21: 1.413 | I21: 1.449 | J21: 1.465 | K21: 1.472 | L21: 1.488 | M21: 1.517 | N21: 1.566 | O21: 1.611 | P21: 1.629 | Q21: 1.596 | R21: 1.536 | S21: 1.488 | T21: 1.454 | U21: 1.449 | V21: 1.44 | W21: 1.437 | X21: 1.466 | Y21: 1.498 | Z21: 1.495 | AA21: 1.471 | AB21: 1.447 | AC21: 1.449 | AD21: 1.434 | AE21: 1.412 | AF21: 1.417 | AG21: 1.414 | AH21: 1.353 | AI21: 1.297 | AJ21: 1.291 | AK21: 1.277 | AL21: 1.232 | AM21: 1.162 | AN21: 1.088 | AO21: 1.032 | AP21: 0.979 | AQ21: 0.953 | AR21: 0.917 | AS21: 0.874 | AT21: 0.845 | AU21: 0.822 | AV21: 0.805 | AW21: 0.788
A22: N1173N | B22: Logiciels et bases de données (net) | C22: 0.304 | D22: 0.363 | E22: 0.417 | F22: 0.458 | G22: 0.484 | H22: 0.511 | I22: 0.566 | J22: 0.629 | K22: 0.745 | L22: 0.843 | M22: 0.931 | N22: 1.04 | O22: 1.133 | P22: 1.153 | Q22: 1.178 | R22: 1.181 | S22: 1.267 | T22: 1.336 | U22: 1.323 | V22: 1.317 | W22: 1.354 | X22: 1.414 | Y22: 1.532 | Z22: 1.68 | AA22: 1.71 | AB22: 1.733 | AC22: 1.788 | AD22: 1.873 | AE22: 1.952 | AF22: 2.069 | AG22: 2.063 | AH22: 1.929 | AI22: 1.861 | AJ22: 1.838 | AK22: 1.883 | AL22: 1.935 | AM22: 2.005 | AN22: 2.078 | AO22: 2.162 | AP22: 2.314 | AQ22: 2.518 | AR22: 2.758 | AS22: 3.01 | AT22: 3.622 | AU22: 4.301 | AV22: 4.99 | AW22: 5.642
A23: N1174N | B23: Œuvres récréatives, littéraires ou artistiques originales (net) | C23: 0 | D23: 0 | E23: 0 | F23: 0 | G23: 0 | H23: 0 | I23: 0 | J23: 0.001 | K23: 0.001 | L23: 0.001 | M23: 0.001 | N23: 0.001 | O23: 0.002 | P23: 0.002 | Q23: 0.003 | R23: 0.002 | S23: 0.002 | T23: 0.002 | U23: 0.002 | V23: 0.002 | W23: 0.002 | X23: 0.002 | Y23: 0.004 | Z23: 0.004 | AA23: 0.005 | AB23: 0.004 | AC23: 0.004 | AD23: 0.005 | AE23: 0.005 | AF23: 0.005 | AG23: 0.005 | AH23: 0.005 | AI23: 0.006 | AJ23: 0.003 | AK23: 0.007 | AL23: 0.006 | AM23: 0.004 | AN23: 0.003 | AO23: 0.003 | AP23: 0.003 | AQ23: 0.003 | AR23: 0.003 | AS23: 0.004 | AT23: 0.005 | AU23: 0.007 | AV23: 0.009 | AW23: 0.009
A24: N12N | B24: Stocks par type de stocks (net) | C24: 8.086 | D24: 9.352 | E24: 10.957 | F24: 12.288 | G24: 12.668 | H24: 12.933 | I24: 12.688 | J24: 12.676 | K24: 12.034 | L24: 11.489 | M24: 11.81 | N24: 12.457 | O24: 12.731 | P24: 12.821 | Q24: 12.698 | R24: 12.262 | S24: 12.493 | T24: 13.558 | U24: 13.832 | V24: 14.131 | W24: 14.302 | X24: 14.624 | Y24: 14.228 | Z24: 13.572 | AA24: 13.159 | AB24: 12.642 | AC24: 12.854 | AD24: 13.257 | AE24: 14.376 | AF24: 16.239 | AG24: 15.901 | AH24: 13.437 | AI24: 13.525 | AJ24: 13.105 | AK24: 12.609 | AL24: 13.244 | AM24: 14.515 | AN24: 14.481 | AO24: 14.038 | AP24: 13.543 | AQ24: 14.16 | AR24: 13.314 | AS24: 12.675 | AT24: 14.947 | AU24: 18.71 | AV24: 18.146 | AW24: 17.7
A25: N13N | B25: Objets de valeur (net) | C25: 43.579 | D25: 49.805 | E25: 52.38 | F25: 50.012 | G25: 55.888 | H25: 66.738 | I25: 64.626 | J25: 59.145 | K25: 59.435 | L25: 61.525 | M25: 58.771 | N25: 53.346 | O25: 49.174 | P25: 46.296 | Q25: 44.798 | R25: 46.319 | S25: 45.291 | T25: 44.925 | U25: 45.384 | V25: 43.562 | W25: 45.052 | X25: 53.075 | Y25: 62.973 | Z25: 78.141 | AA25: 87.042 | AB25: 88.096 | AC25: 95.603 | AD25: 110.368 | AE25: 121.097 | AF25: 119.772 | AG25: 109.941 | AH25: 114.34 | AI25: 133.937 | AJ25: 139.227 | AK25: 135.065 | AL25: 132.926 | AM25: 134.004 | AN25: 132.25 | AO25: 134.265 | AP25: 142.875 | AQ25: 143.086 | AR25: 141.487 | AS25: 152.517 | AT25: 186.041 | AU25: 205.174 | AV25: 201.194 | AW25: 201.514
A26: N2N | B26: Actifs non financiers non produits (net) | C26: 292.247 | D26: 328.127 | E26: 361.523 | F26: 396.874 | G26: 414.164 | H26: 445.798 | I26: 445.58 | J26: 458.458 | K26: 487.256 | L26: 514.029 | M26: 577.002 | N26: 662.898 | O26: 723.212 | P26: 686.818 | Q26: 615.552 | R26: 572.699 | S26: 589.381 | T26: 535.778 | U26: 526.183 | V26: 513.067 | W26: 593.02 | X26: 784.173 | Y26: 970.043 | Z26: 1145.885 | AA26: 1447.105 | AB26: 1871.108 | AC26: 2447.055 | AD26: 3089.554 | AE26: 3546.503 | AF26: 3809.246 | AG26: 3405.406 | AH26: 3279.131 | AI26: 3711.518 | AJ26: 3860.736 | AK26: 3729.211 | AL26: 3604.976 | AM26: 3453.071 | AN26: 3470.559 | AO26: 3612.616 | AP26: 3815.053 | AQ26: 4024.322 | AR26: 4329.34 | AS26: 4714.469 | AT26: 5034.792 | AU26: 5167.898 | AV26: 4725.426 | AW26: 4605.961
A27: N21N | B27: Ressources naturelles (net) | C27: 279.183 | D27: 313.549 | E27: 345.364 | F27: 379.195 | G27: 395.107 | H27: 425.561 | I27: 424.463 | J27: 436.702 | K27: 465.043 | L27: 491.4 | M27: 553.424 | N27: 637.967 | O27: 697.744 | P27: 661.738 | Q27: 591.151 | R27: 548.815 | S27: 565.345 | T27: 511.284 | U27: 501.346 | V27: 487.878 | W27: 567.411 | X27: 758.05 | Y27: 943.345 | Z27: 1118.58 | AA27: 1418.485 | AB27: 1841.711 | AC27: 2416.045 | AD27: 3059.116 | AE27: 3525.981 | AF27: 3788.713 | AG27: 3386.388 | AH27: 3261.502 | AI27: 3695.155 | AJ27: 3845.538 | AK27: 3714.303 | AL27: 3590.349 | AM27: 3438.163 | AN27: 3456.628 | AO27: 3599.27 | AP27: 3802.258 | AQ27: 4012.237 | AR27: 4317.645 | AS27: 4703.203 | AT27: 5023.748 | AU27: 5157.269 | AV27: 4715.143 | AW27: 4596.012
A28: N211N | B28: Terrains (net) | C28: 279.183 | D28: 313.549 | E28: 345.364 | F28: 379.195 | G28: 395.107 | H28: 425.561 | I28: 424.463 | J28: 436.702 | K28: 465.043 | L28: 491.4 | M28: 553.424 | N28: 637.967 | O28: 697.744 | P28: 661.738 | Q28: 591.151 | R28: 548.815 | S28: 565.345 | T28: 511.284 | U28: 501.346 | V28: 487.878 | W28: 567.411 | X28: 758.05 | Y28: 943.345 | Z28: 1118.58 | AA28: 1418.485 | AB28: 1841.711 | AC28: 2416.045 | AD28: 3059.116 | AE28: 3525.981 | AF28: 3788.713 | AG28: 3386.388 | AH28: 3261.502 | AI28: 3695.155 | AJ28: 3845.538 | AK28: 3714.303 | AL28: 3590.349 | AM28: 3438.163 | AN28: 3456.628 | AO28: 3599.27 | AP28: 3802.258 | AQ28: 4012.237 | AR28: 4317.645 | AS28: 4703.203 | AT28: 5023.748 | AU28: 5157.269 | AV28: 4715.143 | AW28: 4596.012
A29: N2111N | B29: Terrains supportant des bâtiments et des ouvrages de génie civil (net) | C29: 128.64 | D29: 151.127 | E29: 175.616 | F29: 199.454 | G29: 207.615 | H29: 230.612 | I29: 229.598 | J29: 249.632 | K29: 281.169 | L29: 325.365 | M29: 397.403 | N29: 478.081 | O29: 518.867 | P29: 496.361 | Q29: 441.469 | R29: 409.912 | S29: 429.935 | T29: 388.362 | U29: 381.513 | V29: 371.815 | W29: 442.4 | X29: 614.149 | Y29: 779.89 | Z29: 940.179 | AA29: 1211.974 | AB29: 1599.404 | AC29: 2131.453 | AD29: 2730.241 | AE29: 3166.355 | AF29: 3406.434 | AG29: 3032.693 | AH29: 2927.326 | AI29: 3321.371 | AJ29: 3451.359 | AK29: 3325.293 | AL29: 3208.688 | AM29: 3061.784 | AN29: 3077.736 | AO29: 3199.167 | AP29: 3377.141 | AQ29: 3562.891 | AR29: 3811.713 | AS29: 4136.415 | AT29: 4409.369 | AU29: 4526.17 | AV29: 4125.316 | AW29: 3992.805
A30: N2112N | B30: Terrains cultivés (net) | C30: 108.161 | D30: 113.866 | E30: 115.719 | F30: 121.744 | G30: 127.08 | H30: 131.072 | I30: 131.384 | J30: 126.043 | K30: 123.524 | L30: 110.95 | M30: 104.062 | N30: 104.239 | O30: 117.094 | P30: 108.667 | Q30: 98.266 | R30: 90.24 | S30: 87.627 | T30: 81.806 | U30: 79.182 | V30: 76.76 | W30: 80.286 | X30: 86.401 | Y30: 92.277 | Z30: 95.815 | AA30: 105.672 | AB30: 116.873 | AC30: 128.165 | AD30: 136.998 | AE30: 139.318 | AF30: 147.135 | AG30: 138.88 | AH30: 125.56 | AI30: 133.664 | AJ30: 140.576 | AK30: 139.727 | AL30: 140.122 | AM30: 136.854 | AN30: 136.038 | AO30: 140.307 | AP30: 144.188 | AQ30: 147.045 | AR30: 167.626 | AS30: 180.821 | AT30: 190.711 | AU30: 194.808 | AV30: 181.371 | AW30: 185.892
A31: N2113N | B31: Terrains et plans d’eau de loisirs (net)
A32: N2119N | B32: Autres terrains et plans d’eau (net) | C32: 42.382 | D32: 48.556 | E32: 54.029 | F32: 57.997 | G32: 60.411 | H32: 63.877 | I32: 63.482 | J32: 61.027 | K32: 60.35 | L32: 55.085 | M32: 51.96 | N32: 55.648 | O32: 61.783 | P32: 56.71 | Q32: 51.417 | R32: 48.664 | S32: 47.782 | T32: 41.116 | U32: 40.651 | V32: 39.304 | W32: 44.726 | X32: 57.501 | Y32: 71.178 | Z32: 82.587 | AA32: 100.84 | AB32: 125.435 | AC32: 156.427 | AD32: 191.877 | AE32: 220.308 | AF32: 235.145 | AG32: 214.814 | AH32: 208.616 | AI32: 240.119 | AJ32: 253.603 | AK32: 249.283 | AL32: 241.539 | AM32: 239.525 | AN32: 242.854 | AO32: 259.797 | AP32: 280.93 | AQ32: 302.302 | AR32: 338.306 | AS32: 385.968 | AT32: 423.668 | AU32: 436.292 | AV32: 408.457 | AW32: 417.316
A33: N212N | B33: Réserves de minerais et de produits énergétiques (net)
A34: N214N | B34: Ressources en eau (net)
A35: N22N | B35: Contrats, baux et licences (net)
A36: N23N | B36: Achats moins ventes de fonds commerciaux et d’autres actifs commerciaux (net) | C36: 13.065 | D36: 14.578 | E36: 16.159 | F36: 17.68 | G36: 19.057 | H36: 20.237 | I36: 21.116 | J36: 21.756 | K36: 22.213 | L36: 22.629 | M36: 23.578 | N36: 24.93 | O36: 25.468 | P36: 25.08 | Q36: 24.401 | R36: 23.884 | S36: 24.037 | T36: 24.494 | U36: 24.838 | V36: 25.189 | W36: 25.61 | X36: 26.124 | Y36: 26.698 | Z36: 27.305 | AA36: 28.619 | AB36: 29.397 | AC36: 31.01 | AD36: 30.437 | AE36: 20.522 | AF36: 20.533 | AG36: 19.019 | AH36: 17.629 | AI36: 16.363 | AJ36: 15.199 | AK36: 14.907 | AL36: 14.627 | AM36: 14.907 | AN36: 13.93 | AO36: 13.346 | AP36: 12.795 | AQ36: 12.085 | AR36: 11.695 | AS36: 11.266 | AT36: 11.045 | AU36: 10.629 | AV36: 10.283 | AW36: 9.948
A38: F | B38: Total des actifs financiers | T38: 1898.591 | U38: 2035.09 | V38: 2180.133 | W38: 2323.332 | X38: 2620.063 | Y38: 2710.446 | Z38: 2643.19 | AA38: 2658.662 | AB38: 2841.549 | AC38: 3006.153 | AD38: 3241.689 | AE38: 3612.911 | AF38: 3819.032 | AG38: 3544.767 | AH38: 3816.727 | AI38: 4077.863 | AJ38: 4117.697 | AK38: 4278.938 | AL38: 4463.766 | AM38: 4663.605 | AN38: 4888.71 | AO38: 5228.665 | AP38: 5469.428 | AQ38: 5428.446 | AR38: 5926.698 | AS38: 6223.352 | AT38: 6728.711 | AU38: 6393.79 | AV38: 6806.904 | AW38: 6977.156 | AY38: =(AW38-AT38)/AT38*100 -> 3.6923119
A39: F1 | B39: Or monétaire et droits de tirage spéciaux (DTS)
A40: F2 | B40: Numéraire et dépôts | T40: 645.421 | U40: 676.704 | V40: 717.746 | W40: 749.68 | X40: 780.74 | Y40: 772.519 | Z40: 791.219 | AA40: 839.878 | AB40: 878.699 | AC40: 914.625 | AD40: 953.747 | AE40: 973.287 | AF40: 1014.523 | AG40: 1056.051 | AH40: 1077.832 | AI40: 1110.547 | AJ40: 1166.983 | AK40: 1213.712 | AL40: 1246.982 | AM40: 1263.943 | AN40: 1307.157 | AO40: 1364.229 | AP40: 1423 | AQ40: 1492.054 | AR40: 1574.227 | AS40: 1728.925 | AT40: 1843.063 | AU40: 1930.408 | AV40: 1982.019 | AW40: 2012.321 | AY40: =(AW40-AT40)/AT40*100 -> 9.1835168
A41: F3 | B41: Titres de créance | T41: 109.351 | U41: 101.379 | V41: 88.386 | W41: 87.657 | X41: 74.113 | Y41: 90.526 | Z41: 95.263 | AA41: 82.623 | AB41: 70.709 | AC41: 68.41 | AD41: 69.148 | AE41: 63.983 | AF41: 68.046 | AG41: 71.658 | AH41: 83.423 | AI41: 76.493 | AJ41: 75.685 | AK41: 83.962 | AL41: 83.098 | AM41: 72.428 | AN41: 59.989 | AO41: 54.308 | AP41: 47.334 | AQ41: 40.726 | AR41: 39.341 | AS41: 34.369 | AT41: 32.95 | AU41: 34.653 | AV41: 45.438 | AW41: 50.208
A42: F4 | B42: Crédits | T42: 26.59 | U42: 26.831 | V42: 33.974 | W42: 24.579 | X42: 19.178 | Y42: 20.765 | Z42: 20.455 | AA42: 18.915 | AB42: 21.235 | AC42: 19.503 | AD42: 20.144 | AE42: 23.292 | AF42: 22.85 | AG42: 32.324 | AH42: 25.822 | AI42: 26.49 | AJ42: 27.78 | AK42: 28.604 | AL42: 29.362 | AM42: 30.392 | AN42: 31.413 | AO42: 10.238 | AP42: 10.531 | AQ42: 10.638 | AR42: 10.6 | AS42: 11.005 | AT42: 11.006 | AU42: 10.862 | AV42: 11.656 | AW42: 11.289
A43: F5 | B43: Actions et parts de fonds d’investissement | T43: 657.747 | U43: 703.686 | V43: 733.313 | W43: 797.539 | X43: 976.446 | Y43: 982.231 | Z43: 844.942 | AA43: 774.896 | AB43: 858.671 | AC43: 921.235 | AD43: 995.607 | AE43: 1197.463 | AF43: 1239.899 | AG43: 887.278 | AH43: 964.384 | AI43: 1028.548 | AJ43: 963.725 | AK43: 1076.394 | AL43: 1132.675 | AM43: 1214.945 | AN43: 1329.665 | AO43: 1398.176 | AP43: 1534.772 | AQ43: 1447.947 | AR43: 1658.202 | AS43: 1711.723 | AT43: 2036.19 | AU43: 1886.689 | AV43: 2106.629 | AW43: 2136.859 | AY43: =(AW43-AT43)/AT43*100 -> 4.9439885
...

Sheet Variations
A1: 8.220 – Comptes de patrimoine et de variation de patrimoine des ménages (S14)
A2: Unité : Milliard d'euros
B4: Annuel | C4: 1978 | D4: 1979 | E4: 1979 | F4: 1979 | G4: 1979 | H4: 1979 | I4: 1980 | J4: 1980 | K4: 1980 | L4: 1980 | M4: 1980 | N4: 1981 | O4: 1981 | P4: 1981 | Q4: 1981 | R4: 1981 | S4: 1982 | T4: 1982 | U4: 1982 | V4: 1982 | W4: 1982 | X4: 1983 | Y4: 1983 | Z4: 1983 | AA4: 1983 | AB4: 1983 | AC4: 1984 | AD4: 1984 | AE4: 1984 | AF4: 1984 | AG4: 1984 | AH4: 1985 | AI4: 1985 | AJ4: 1985 | AK4: 1985 | AL4: 1985 | AM4: 1986 | AN4: 1986 | AO4: 1986 | AP4: 1986 | AQ4: 1986 | AR4: 1987 | AS4: 1987 | AT4: 1987 | AU4: 1987 | AV4: 1987 | AW4: 1988 | AX4: 1988 | AY4: 1988 | AZ4: 1988 | BA4: 1988 | BB4: 1989 | BC4: 1989 | BD4: 1989 | BE4: 1989 | BF4: 1989 | BG4: 1990 | BH4: 1990 | BI4: 1990 | BJ4: 1990 | BK4: 1990 | BL4: 1991 | BM4: 1991 | BN4: 1991 | BO4: 1991 | BP4: 1991 | BQ4: 1992 | BR4: 1992 | BS4: 1992 | BT4: 1992 | BU4: 1992 | BV4: 1993 | BW4: 1993 | BX4: 1993 | BY4: 1993 | BZ4: 1993 | CA4: 1994 | CB4: 1994 | CC4: 1994 | CD4: 1994 | CE4: 1994 | CF4: 1995 | CG4: 1995 | CH4: 1995 | CI4: 1995 | CJ4: 1995 | CK4: 1996 | CL4: 1996 | CM4: 1996 | CN4: 1996 | CO4: 1996 | CP4: 1997 | CQ4: 1997 | CR4: 1997 | CS4: 1997 | CT4: 1997 | CU4: 1998 | CV4: 1998 | CW4: 1998 | CX4: 1998 | CY4: 1998 | CZ4: 1999 | DA4: 1999 | DB4: 1999 | DC4: 1999 | DD4: 1999 | DE4: 2000 | DF4: 2000 | DG4: 2000 | DH4: 2000 | DI4: 2000 | DJ4: 2001 | DK4: 2001 | DL4: 2001 | DM4: 2001 | DN4: 2001 | DO4: 2002 | DP4: 2002 | DQ4: 2002 | DR4: 2002 | DS4: 2002 | DT4: 2003 | DU4: 2003 | DV4: 2003 | DW4: 2003 | DX4: 2003 | DY4: 2004 | DZ4: 2004 | EA4: 2004 | EB4: 2004 | EC4: 2004 | ED4: 2005 | EE4: 2005 | EF4: 2005 | EG4: 2005 | EH4: 2005 | EI4: 2006 | EJ4: 2006 | EK4: 2006 | EL4: 2006 | EM4: 2006 | EN4: 2007 | EO4: 2007 | EP4: 2007 | EQ4: 2007 | ER4: 2007 | ES4: 2008 | ET4: 2008 | EU4: 2008 | EV4: 2008 | EW4: 2008 | EX4: 2009 | EY4: 2009 | EZ4: 2009 | FA4: 2009 | FB4: 2009 | FC4: 2010 | FD4: 2010 | FE4: 2010 | FF4: 2010 | FG4: 2010 | FH4: 2011 | FI4: 2011 | FJ4: 2011 | FK4: 2011 | FL4: 2011 | FM4: 2012 | FN4: 2012 | FO4: 2012 | FP4: 2012 | FQ4: 2012 | FR4: 2013 | FS4: 2013 | FT4: 2013 | FU4: 2013 | FV4: 2013 | FW4: 2014 | FX4: 2014 | FY4: 2014 | FZ4: 2014 | GA4: 2014 | GB4: 2015 | GC4: 2015 | GD4: 2015 | GE4: 2015 | GF4: 2015 | GG4: 2016 | GH4: 2016 | GI4: 2016 | GJ4: 2016 | GK4: 2016 | GL4: 2017 | GM4: 2017 | GN4: 2017 | GO4: 2017 | GP4: 2017 | GQ4: 2018 | GR4: 2018 | GS4: 2018 | GT4: 2018 | GU4: 2018 | GV4: 2019 | GW4: 2019 | GX4: 2019 | GY4: 2019 | GZ4: 2019 | HA4: 2020 | HB4: 2020 | HC4: 2020 | HD4: 2020 | HE4: 2020 | HF4: 2021 | HG4: 2021 | HH4: 2021 | HI4: 2021 | HJ4: 2021 | HK4: 2022 | HL4: 2022 | HM4: 2022 | HN4: 2022 | HO4: 2022 | HP4: 2023 | HQ4: 2023 | HR4: 2023 | HS4: 2023 | HT4: 2023 | HU4: 2024 | HV4: 2024 | HW4: 2024 | HX4: 2024 | HY4: 2024
B5: Opération comptable | C5: Patrimoine en fin d'année | D5: Flux d’actifs | E5: Consommation de capital fixe | F5: Réévaluation | G5: Autres changements de volume et ajustements | H5: Patrimoine en fin d'année | I5: Flux d’actifs | J5: Consommation de capital fixe | K5: Réévaluation | L5: Autres changements de volume et ajustements | M5: Patrimoine en fin d'année | N5: Flux d’actifs | O5: Consommation de capital fixe | P5: Réévaluation | Q5: Autres changements de volume et ajustements | R5: Patrimoine en fin d'année | S5: Flux d’actifs | T5: Consommation de capital fixe | U5: Réévaluation | V5: Autres changements de volume et ajustements | W5: Patrimoine en fin d'année | X5: Flux d’actifs | Y5: Consommation de capital fixe | Z5: Réévaluation | AA5: Autres changements de volume et ajustements | AB5: Patrimoine en fin d'année | AC5: Flux d’actifs | AD5: Consommation de capital fixe | AE5: Réévaluation | AF5: Autres changements de volume et ajustements | AG5: Patrimoine en fin d'année | AH5: Flux d’actifs | AI5: Consommation de capital fixe | AJ5: Réévaluation | AK5: Autres changements de volume et ajustements | AL5: Patrimoine en fin d'année | AM5: Flux d’actifs | AN5: Consommation de capital fixe | AO5: Réévaluation | AP5: Autres changements de volume et ajustements | AQ5: Patrimoine en fin d'année | AR5: Flux d’actifs | AS5: Consommation de capital fixe | AT5: Réévaluation | AU5: Autres changements de volume et ajustements | AV5: Patrimoine en fin d'année | AW5: Flux d’actifs | AX5: Consommation de capital fixe | AY5: Réévaluation | AZ5: Autres changements de volume et ajustements | BA5: Patrimoine en fin d'année | BB5: Flux d’actifs | BC5: Consommation de capital fixe | BD5: Réévaluation | BE5: Autres changements de volume et ajustements | BF5: Patrimoine en fin d'année | BG5: Flux d’actifs | BH5: Consommation de capital fixe | BI5: Réévaluation | BJ5: Autres changements de volume et ajustements | BK5: Patrimoine en fin d'année | BL5: Flux d’actifs | BM5: Consommation de capital fixe | BN5: Réévaluation | BO5: Autres changements de volume et ajustements | BP5: Patrimoine en fin d'année | BQ5: Flux d’actifs | BR5: Consommation de capital fixe | BS5: Réévaluation | BT5: Autres changements de volume et ajustements | BU5: Patrimoine en fin d'année | BV5: Flux d’actifs | BW5: Consommation de capital fixe | BX5: Réévaluation | BY5: Autres changements de volume et ajustements | BZ5: Patrimoine en fin d'année | CA5: Flux d’actifs | CB5: Consommation de capital fixe | CC5: Réévaluation | CD5: Autres changements de volume et ajustements | CE5: Patrimoine en fin d'année | CF5: Flux d’actifs | CG5: Consommation de capital fixe | CH5: Réévaluation | CI5: Autres changements de volume et ajustements | CJ5: Patrimoine en fin d'année | CK5: Flux d’actifs | CL5: Consommation de capital fixe | CM5: Réévaluation | CN5: Autres changements de volume et ajustements | CO5: Patrimoine en fin d'année | CP5: Flux d’actifs | CQ5: Consommation de capital fixe | CR5: Réévaluation | CS5: Autres changements de volume et ajustements | CT5: Patrimoine en fin d'année | CU5: Flux d’actifs | CV5: Consommation de capital fixe | CW5: Réévaluation | CX5: Autres changements de volume et ajustements | CY5: Patrimoine en fin d'année | CZ5: Flux d’actifs | DA5: Consommation de capital fixe | DB5: Réévaluation | DC5: Autres changements de volume et ajustements | DD5: Patrimoine en fin d'année | DE5: Flux d’actifs | DF5: Consommation de capital fixe | DG5: Réévaluation | DH5: Autres changements de volume et ajustements | DI5: Patrimoine en fin d'année | DJ5: Flux d’actifs | DK5: Consommation de capital fixe | DL5: Réévaluation | DM5: Autres changements de volume et ajustements | DN5: Patrimoine en fin d'année | DO5: Flux d’actifs | DP5: Consommation de capital fixe | DQ5: Réévaluation | DR5: Autres changements de volume et ajustements | DS5: Patrimoine en fin d'année | DT5: Flux d’actifs | DU5: Consommation de capital fixe | DV5: Réévaluation | DW5: Autres changements de volume et ajustements | DX5: Patrimoine en fin d'année | DY5: Flux d’actifs | DZ5: Consommation de capital fixe | EA5: Réévaluation | EB5: Autres changements de volume et ajustements | EC5: Patrimoine en fin d'année | ED5: Flux d’actifs | EE5: Consommation de capital fixe | EF5: Réévaluation | EG5: Autres changements de volume et ajustements | EH5: Patrimoine en fin d'année | EI5: Flux d’actifs | EJ5: Consommation de capital fixe | EK5: Réévaluation | EL5: Autres changements de volume et ajustements | EM5: Patrimoine en fin d'année | EN5: Flux d’actifs | EO5: Consommation de capital fixe | EP5: Réévaluation | EQ5: Autres changements de volume et ajustements | ER5: Patrimoine en fin d'année | ES5: Flux d’actifs | ET5: Consommation de capital fixe | EU5: Réévaluation | EV5: Autres changements de volume et ajustements | EW5: Patrimoine en fin d'année | EX5: Flux d’actifs | EY5: Consommation de capital fixe | EZ5: Réévaluation | FA5: Autres changements de volume et ajustements | FB5: Patrimoine en fin d'année | FC5: Flux d’actifs | FD5: Consommation de capital fixe | FE5: Réévaluation | FF5: Autres changements de volume et ajustements | FG5: Patrimoine en fin d'année | FH5: Flux d’actifs | FI5: Consommation de capital fixe | FJ5: Réévaluation | FK5: Autres changements de volume et ajustements | FL5: Patrimoine en fin d'année | FM5: Flux d’actifs | FN5: Consommation de capital fixe | FO5: Réévaluation | FP5: Autres changements de volume et ajustements | FQ5: Patrimoine en fin d'année | FR5: Flux d’actifs | FS5: Consommation de capital fixe | FT5: Réévaluation | FU5: Autres changements de volume et ajustements | FV5: Patrimoine en fin d'année | FW5: Flux d’actifs | FX5: Consommation de capital fixe | FY5: Réévaluation | FZ5: Autres changements de volume et ajustements | GA5: Patrimoine en fin d'année | GB5: Flux d’actifs | GC5: Consommation de capital fixe | GD5: Réévaluation | GE5: Autres changements de volume et ajustements | GF5: Patrimoine en fin d'année | GG5: Flux d’actifs | GH5: Consommation de capital fixe | GI5: Réévaluation | GJ5: Autres changements de volume et ajustements | GK5: Patrimoine en fin d'année | GL5: Flux d’actifs | GM5: Consommation de capital fixe | GN5: Réévaluation | GO5: Autres changements de volume et ajustements | GP5: Patrimoine en fin d'année | GQ5: Flux d’actifs | GR5: Consommation de capital fixe | GS5: Réévaluation | GT5: Autres changements de volume et ajustements | GU5: Patrimoine en fin d'année | GV5: Flux d’actifs | GW5: Consommation de capital fixe | GX5: Réévaluation | GY5: Autres changements de volume et ajustements | GZ5: Patrimoine en fin d'année | HA5: Flux d’actifs | HB5: Consommation de capital fixe | HC5: Réévaluation | HD5: Autres changements de volume et ajustements | HE5: Patrimoine en fin d'année | HF5: Flux d’actifs | HG5: Consommation de capital fixe | HH5: Réévaluation | HI5: Autres changements de volume et ajustements | HJ5: Patrimoine en fin d'année | HK5: Flux d’actifs | HL5: Consommation de capital fixe | HM5: Réévaluation | HN5: Autres changements de volume et ajustements | HO5: Patrimoine en fin d'année | HP5: Flux d’actifs | HQ5: Consommation de capital fixe | HR5: Réévaluation | HS5: Autres changements de volume et ajustements | HT5: Patrimoine en fin d'année | HU5: Flux d’actifs | HV5: Consommation de capital fixe | HW5: Réévaluation | HX5: Autres changements de volume et ajustements | HY5: Patrimoine en fin d'année
A6: INSTR_ASSET | B6: Classe d'actifs passifs
A7: N | B7: Total des actifs non financiers | C7: 778.641 | D7: 35.59 | E7: -12.997 | F7: 92.168 | G7: 6.509 | H7: 899.909 | I7: 40.86 | J7: -15.577 | K7: 93.994 | L7: 6.866 | M7: 1026.051 | N7: 42.3 | O7: -17.875 | P7: 99.091 | Q7: 5.032 | R7: 1154.598 | S7: 44.939 | T7: -20.493 | U7: 92.418 | V7: 3.072 | W7: 1274.534 | X7: 46.142 | Y7: -22.4 | Z7: 94.169 | AA7: 6.8 | AB7: 1399.243 | AC7: 47.903 | AD7: -23.945 | AE7: 37.593 | AF7: 5.937 | AG7: 1466.728 | AH7: 47.04 | AI7: -24.901 | AJ7: 43.23 | AK7: 0.229 | AL7: 1532.327 | AM7: 49.945 | AN7: -25.942 | AO7: 64.062 | AP7: 0.381 | AQ7: 1620.772 | AR7: 55.096 | AS7: -27.204 | AT7: 76.676 | AU7: -8.864 | AV7: 1716.474 | AW7: 60.172 | AX7: -28.902 | AY7: 102.356 | AZ7: -1.862 | BA7: 1848.238 | BB7: 66.689 | BC7: -30.882 | BD7: 117.463 | BE7: 4.078 | BF7: 2005.584 | BG7: 67.538 | BH7: -32.977 | BI7: 90.676 | BJ7: 14.952 | BK7: 2145.773 | BL7: 64.255 | BM7: -35.037 | BN7: -5.962 | BO7: 2.088 | BP7: 2171.116 | BQ7: 61.312 | BR7: -35.734 | BS7: -57.999 | BT7: 0.805 | BU7: 2139.5 | BV7: 58.797 | BW7: -36.024 | BX7: -31.442 | BY7: 2.68 | BZ7: 2133.511 | CA7: 62.894 | CB7: -36.485 | CC7: 23.352 | CD7: 3.587 | CE7: 2186.859 | CF7: 63.817 | CG7: -36.397 | CH7: -35.813 | CI7: 3.403 | CJ7: 2181.869 | CK7: 63.947 | CL7: -36.801 | CM7: 18.331 | CN7: 3.338 | CO7: 2230.685 | CP7: 66.139 | CQ7: -37.839 | CR7: 11.028 | CS7: 0.986 | CT7: 2270.999 | CU7: 70.728 | CV7: -38.753 | CW7: 94.181 | CX7: 3.243 | CY7: 2400.399 | CZ7: 76.511 | DA7: -39.723 | DB7: 213.941 | DC7: 4.213 | DD7: 2655.34 | DE7: 78.565 | DF7: -41.404 | DG7: 226.749 | DH7: 10.394 | DI7: 2929.644 | DJ7: 82.84 | DK7: -43.332 | DL7: 232.292 | DM7: 14.174 | DN7: 3215.616 | DO7: 86.34 | DP7: -45.262 | DQ7: 348.102 | DR7: 18.936 | DS7: 3623.73 | DT7: 90.962 | DU7: -47.459 | DV7: 484.647 | DW7: 18.898 | DX7: 4170.775 | DY7: 101.039 | DZ7: -50.563 | EA7: 646.311 | EB7: 30.21 | EC7: 4897.774 | ED7: 105.096 | EE7: -53.725 | EF7: 718.75 | EG7: 32.863 | EH7: 5700.758 | EI7: 115.884 | EJ7: -57.561 | EK7: 535.714 | EL7: 33.489 | EM7: 6328.283 | EN7: 123.662 | EO7: -61.479 | EP7: 284.832 | EQ7: 93.928 | ER7: 6769.226 | ES7: 126.926 | ET7: -65.844 | EU7: -379.007 | EV7: 37.753 | EW7: 6489.052 | EX7: 108.429 | EY7: -65.454 | EZ7: -68.761 | FA7: -18.126 | FB7: 6445.14 | FC7: 112.626 | FD7: -67.435 | FE7: 514.399 | FF7: 8.169 | FG7: 7012.899 | FH7: 117.727 | FI7: -69.454 | FJ7: 185.511 | FK7: 39.609 | FL7: 7286.289 | FM7: 116.564 | FN7: -70.356 | FO7: -143.008 | FP7: 41.397 | FQ7: 7230.886 | FR7: 116.684 | FS7: -70.446 | FT7: -146.945 | FU7: 55.48 | FV7: 7185.659 | FW7: 115.841 | FX7: -72.278 | FY7: -160.488 | FZ7: 37.632 | GA7: 7106.361 | GB7: 116.111 | GC7: -73.151 | GD7: -17.823 | GE7: 36.214 | GF7: 7167.711 | GG7: 120.115 | GH7: -74.181 | GI7: 148.089 | GJ7: 35.243 | GK7: 7396.974 | GL7: 129.622 | GM7: -77.468 | GN7: 225.227 | GO7: 51.034 | GP7: 7725.384 | GQ7: 136.075 | GR7: -81.211 | GS7: 226.325 | GT7: 53.105 | GU7: 8059.674 | GV7: 142.519 | GW7: -85.765 | GX7: 282.598 | GY7: 76.795 | GZ7: 8475.817 | HA7: 136.937 | HB7: -89.973 | HC7: 432.481 | HD7: 72.782 | HE7: 9028.041 | HF7: 163.6 | HG7: -96.946 | HH7: 558.704 | HI7: 82.941 | HJ7: 9736.338 | HK7: 170.879 | HL7: -106.424 | HM7: 346.933 | HN7: 87.294 | HO7: 10235.023 | HP7: 160.34 | HQ7: -109.65 | HR7: -425.358 | HS7: 71.133 | HT7: 9931.491 | HU7: 150.69 | HV7: -108.746 | HW7: -183.907 | HX7: 78.249 | HY7: 9867.778
A8: N1 | B8: Actifs non financiers produits | C8: 486.393 | D8: 36.035 | E8: -12.997 | F8: 62.352 | H8: 571.783 | I8: 41.352 | J8: -15.577 | K8: 66.971 | M8: 664.528 | N8: 42.791 | O8: -17.875 | P8: 68.281 | R8: 757.724 | S8: 45.449 | T8: -20.493 | U8: 77.691 | W8: 860.371 | X8: 46.666 | Y8: -22.4 | Z8: 68.811 | AB8: 953.445 | AC8: 48.472 | AD8: -23.945 | AE8: 43.179 | AG8: 1021.148 | AH8: 47.493 | AI8: -24.901 | AJ8: 30.129 | AL8: 1073.869 | AM8: 50.407 | AN8: -25.942 | AO8: 35.182 | AQ8: 1133.516 | AR8: 55.567 | AS8: -27.204 | AT8: 40.57 | AV8: 1202.445 | AW8: 60.749 | AX8: -28.902 | AY8: 36.943 | BA8: 1271.235 | BB8: 67.686 | BC8: -30.882 | BD8: 34.648 | BF8: 1342.686 | BG8: 68.551 | BH8: -32.977 | BI8: 44.301 | BK8: 1422.561 | BL8: 65.381 | BM8: -35.037 | BN8: 31.393 | BP8: 1484.298 | BQ8: 62.218 | BR8: -35.734 | BS8: 13.166 | BU8: 1523.948 | BV8: 59.565 | BW8: -36.024 | BX8: 13.324 | BZ8: 1560.813 | CA8: 63.369 | CB8: -36.485 | CC8: 9.782 | CE8: 1597.478 | CF8: 64.825 | CG8: -36.397 | CH8: 20.186 | CJ8: 1646.091 | CK8: 64.715 | CL8: -36.801 | CM8: 30.497 | CO8: 1704.501 | CP8: 67.828 | CQ8: -37.839 | CR8: 23.442 | CT8: 1757.932 | CU8: 72.381 | CV8: -38.753 | CW8: 15.817 | CY8: 1807.379 | CZ8: 78.152 | DA8: -39.723 | DB8: 26.196 | DC8: -0.837 | DD8: 1871.167 | DE8: 81.241 | DF8: -41.404 | DG8: 48.597 | DH8: 0 | DI8: 1959.601 | DJ8: 84.652 | DK8: -43.332 | DL8: 68.812 | DM8: 0 | DN8: 2069.731 | DO8: 88.516 | DP8: -45.262 | DQ8: 63.642 | DR8: 0 | DS8: 2176.625 | DT8: 93.087 | DU8: -47.459 | DV8: 77.416 | DW8: 0 | DX8: 2299.668 | DY8: 103.619 | DZ8: -50.563 | EA8: 97.994 | EB8: 0 | EC8: 2450.719 | ED8: 107.981 | EE8: -53.725 | EF8: 106.23 | EG8: 0 | EH8: 2611.205 | EI8: 119.303 | EJ8: -57.561 | EK8: 108.834 | EL8: 0 | EM8: 2781.78 | EN8: 127.655 | EO8: -61.479 | EP8: 112.024 | EQ8: 0 | ER8: 2959.98 | ES8: 129.829 | ET8: -65.844 | EU8: 59.683 | EV8: 0 | EW8: 3083.646 | EX8: 111.99 | EY8: -65.454 | EZ8: 35.999 | FA8: -0.173 | FB8: 3166.008 | FC8: 115.78 | FD8: -67.435 | FE8: 87.028 | FG8: 3301.381 | FH8: 121.61 | FI8: -69.454 | FJ8: 72.019 | FL8: 3425.553 | FM8: 120.515 | FN8: -70.356 | FO8: 25.964 | FQ8: 3501.676 | FR8: 120.093 | FS8: -70.446 | FT8: 29.36 | FV8: 3580.683 | FW8: 119.506 | FX8: -72.278 | FY8: 25.385 | GA8: 3653.291 | GB8: 119.455 | GC8: -73.151 | GD8: -2.441 | GF8: 3697.152 | GG8: 123.278 | GH8: -74.181 | GI8: 38.112 | GK8: 3784.357 | GL8: 133.084 | GM8: -77.468 | GN8: 70.364 | GP8: 3910.332 | GQ8: 139.536 | GR8: -81.211 | GS8: 66.701 | GU8: 4035.352 | GV8: 146.24 | GW8: -85.765 | GX8: 50.654 | GZ8: 4146.477 | HA8: 139.783 | HB8: -89.973 | HC8: 117.289 | HE8: 4313.572 | HF8: 166.664 | HG8: -96.946 | HH8: 318.258 | HJ8: 4701.545 | HK8: 173.702 | HL8: -106.424 | HM8: 298.299 | HO8: 5067.126 | HP8: 163.832 | HQ8: -109.65 | HR8: 84.755 | HT8: 5206.065 | HU8: 154.683 | HV8: -108.746 | HW8: 9.813 | HY8: 5261.817
A9: N11 | B9: Actifs fixes par type d’actifs | C9: 434.729 | D9: 34.882 | E9: -12.997 | F9: 56.013 | H9: 512.626 | I9: 40.117 | J9: -15.577 | K9: 64.026 | M9: 601.191 | N9: 42.884 | O9: -17.875 | P9: 69.224 | R9: 695.424 | S9: 45.21 | T9: -20.493 | U9: 71.675 | W9: 791.815 | X9: 46.871 | Y9: -22.4 | Z9: 57.49 | AB9: 873.774 | AC9: 48.151 | AD9: -23.945 | AE9: 45.857 | AG9: 943.834 | AH9: 48.187 | AI9: -24.901 | AJ9: 34.927 | AL9: 1002.048 | AM9: 50.59 | AN9: -25.942 | AO9: 35.353 | AQ9: 1062.048 | AR9: 54.313 | AS9: -27.204 | AT9: 40.278 | AV9: 1129.432 | AW9: 59.393 | AX9: -28.902 | AY9: 40.732 | BA9: 1200.655 | BB9: 66.141 | BC9: -30.882 | BD9: 40.971 | BF9: 1276.883 | BG9: 67.084 | BH9: -32.977 | BI9: 49.665 | BK9: 1360.656 | BL9: 64.256 | BM9: -35.037 | BN9: 35.307 | BP9: 1425.182 | BQ9: 61.626 | BR9: -35.734 | BS9: 15.379 | BU9: 1466.453 | BV9: 59.08 | BW9: -36.024 | BX9: 12.724 | BZ9: 1502.232 | CA9: 62.421 | CB9: -36.485 | CC9: 11.528 | CE9: 1539.694 | CF9: 63.583 | CG9: -36.397 | CH9: 20.728 | CJ9: 1587.608 | CK9: 63.714 | CL9: -36.801 | CM9: 30.765 | CO9: 1645.286 | CP9: 67.097 | CQ9: -37.839 | CR9: 25.695 | CT9: 1700.239 | CU9: 71.043 | CV9: -38.753 | CW9: 15.494 | CY9: 1748.024 | CZ9: 76.503 | DA9: -39.723 | DB9: 18.663 | DD9: 1803.467 | DE9: 79.713 | DF9: -41.404 | DG9: 40.625 | DI9: 1882.4 | DJ9: 82.439 | DK9: -43.332 | DL9: 56.513 | DN9: 1978.018 | DO9: 86.718 | DP9: -45.262 | DQ9: 56.952 | DS9: 2076.425 | DT9: 91.506 | DU9: -47.459 | DV9: 78.459 | DX9: 2198.93 | DY9: 99.044 | DZ9: -50.563 | EA9: 94.85 | EC9: 2342.262 | ED9: 106.658 | EE9: -53.725 | EF9: 92.386 | EH9: 2487.58 | EI9: 117.744 | EJ9: -57.561 | EK9: 98.544 | EM9: 2646.307 | EN9: 125.968 | EO9: -61.479 | EP9: 113.172 | ER9: 2823.968 | ES9: 128.577 | ET9: -65.844 | EU9: 71.105 | EW9: 2957.804 | EX9: 111.746 | EY9: -65.454 | EZ9: 34.134 | FB9: 3038.231 | FC9: 115.104 | FD9: -67.435 | FE9: 68.019 | FG9: 3153.919 | FH9: 120.322 | FI9: -69.454 | FJ9: 68.437 | FL9: 3273.221 | FM9: 120.238 | FN9: -70.356 | FO9: 30.9 | FQ9: 3354.002 | FR9: 119.683 | FS9: -70.446 | FT9: 31.274 | FV9: 3434.513 | FW9: 118.852 | FX9: -72.278 | FY9: 23.691 | GA9: 3504.772 | GB9: 118.08 | GC9: -73.151 | GD9: 0.722 | GF9: 3550.421 | GG9: 122.315 | GH9: -74.181 | GI9: 37.503 | GK9: 3636.054 | GL9: 131.853 | GM9: -77.468 | GN9: 63.48 | GP9: 3753.914 | GQ9: 137.356 | GR9: -81.211 | GS9: 68.052 | GU9: 3878.106 | GV9: 145.017 | GW9: -85.765 | GX9: 54.321 | GZ9: 3991.675 | HA9: 138.644 | HB9: -89.973 | HC9: 108.038 | HE9: 4148.38 | HF9: 164.487 | HG9: -96.946 | HH9: 284.639 | HJ9: 4500.558 | HK9: 170.437 | HL9: -106.424 | HM9: 278.668 | HO9: 4843.242 | HP9: 161.766 | HQ9: -109.65 | HR9: 91.364 | HT9: 4986.725 | HU9: 153.122 | HV9: -108.746 | HW9: 11.5 | HY9: 5042.603
A10: N11K | B10: Constructions | C10: 411.214 | D10: 31.625 | E10: -10.377 | F10: 53.915 | H10: 486.378 | I10: 36.337 | J10: -12.487 | K10: 60.887 | M10: 571.114 | N10: 38.654 | O10: -14.3 | P10: 65.683 | R10: 661.152 | S10: 40.536 | T10: -16.365 | U10: 67.439 | W10: 752.762 | X10: 42.122 | Y10: -17.939 | Z10: 55.566 | AB10: 832.511 | AC10: 43.091 | AD10: -19.194 | AE10: 44.539 | AG10: 900.946 | AH10: 42.813 | AI10: -19.95 | AJ10: 33.981 | AL10: 957.791 | AM10: 44.865 | AN10: -20.729 | AO10: 35.253 | AQ10: 1017.179 | AR10: 48.14 | AS10: -21.78 | AT10: 40.099 | AV10: 1083.637 | AW10: 52.674 | AX10: -23.241 | AY10: 38.798 | BA10: 1151.866 | BB10: 58.615 | BC10: -24.885 | BD10: 39.531 | BF10: 1225.126 | BG10: 59.594 | BH10: -26.762 | BI10: 49.594 | BK10: 1307.552 | BL10: 57.85 | BM10: -28.578 | BN10: 35.813 | BP10: 1372.637 | BQ10: 55.81 | BR10: -29.365 | BS10: 16.564 | BU10: 1415.647 | BV10: 53.741 | BW10: -29.859 | BX10: 13.821 | BZ10: 1453.348 | CA10: 56.292 | CB10: -30.347 | CC10: 12.203 | CE10: 1491.495 | CF10: 57.183 | CG10: -30.33 | CH10: 22.482 | CJ10: 1540.829 | CK10: 57.799 | CL10: -30.738 | CM10: 32.089 | CO10: 1599.979 | CP10: 61.211 | CQ10: -31.846 | CR10: 26.095 | CT10: 1655.439 | CU10: 65.003 | CV10: -32.82 | CW10: 15.915 | CY10: 1703.537 | CZ10: 70.717 | DA10: -33.84 | DB10: 18.916 | DD10: 1759.329 | DE10: 73.832 | DF10: -35.325 | DG10: 39.991 | DI10: 1837.827 | DJ10: 76.758 | DK10: -37.179 | DL10: 56.494 | DN10: 1933.9 | DO10: 81.11 | DP10: -39.117 | DQ10: 56.968 | DS10: 2032.861 | DT10: 85.678 | DU10: -41.299 | DV10: 78.301 | DX10: 2155.541 | DY10: 93.458 | DZ10: -44.398 | EA10: 94.56 | EC10: 2299.161 | ED10: 101.01 | EE10: -47.42 | EF10: 92.055 | EH10: 2444.805 | EI10: 112.143 | EJ10: -51.237 | EK10: 98.314 | EM10: 2604.025 | EN10: 119.986 | EO10: -55.089 | EP10: 112.815 | ER10: 2781.737 | ES10: 122.872 | ET10: -59.541 | EU10: 71.372 | EW10: 2916.439 | EX10: 106.736 | EY10: -59.222 | EZ10: 33.752 | FB10: 2997.704 | FC10: 110.406 | FD10: -61.415 | FE10: 68.022 | FG10: 3114.717 | FH10: 115.104 | FI10: -63.492 | FJ10: 67.994 | FL10: 3234.321 | FM10: 114.64 | FN10: -64.404 | FO10: 30.628 | FQ10: 3315.185 | FR10: 114.285 | FS10: -64.559 | FT10: 31.162 | FV10: 3396.072 | FW10: 113.638 | FX10: -66.466 | FY10: 24.016 | GA10: 3467.257 | GB10: 112.833 | GC10: -67.458 | GD10: 1.33 | GF10: 3513.96 | GG10: 117.133 | GH10: -68.594 | GI10: 37.818 | GK10: 3600.314 | GL10: 126.322 | GM10: -71.862 | GN10: 63.413 | GP10: 3718.184 | GQ10: 131.591 | GR10: -75.471 | GS10: 67.753 | GU10: 3842.055 | GV10: 138.797 | GW10: -79.863 | GX10: 53.59 | GZ10: 3954.577 | HA10: 132.237 | HB10: -83.882 | HC10: 107.612 | HE10: 4110.54 | HF10: 157.546 | HG10: -90.529 | HH10: 283.72 | HJ10: 4461.275 | HK10: 164.075 | HL10: -99.735 | HM10: 276.586 | HO10: 4802.204 | HP10: 154.843 | HQ10: -102.469 | HR10: 90.551 | HT10: 4945.131 | HU10: 146.534 | HV10: -101.449 | HW10: 10.933 | HY10: 5001.149
A11: N111 | B11: Logements | C11: 366.873 | D11: 29.037 | E11: -7.845 | F11: 46.731 | H11: 434.796 | I11: 33.356 | J11: -9.506 | K11: 52.753 | M11: 511.398 | N11: 35.499 | O11: -10.938 | P11: 57.621 | R11: 593.579 | S11: 37.202 | T11: -12.562 | U11: 59.705 | W11: 677.924 | X11: 38.682 | Y11: -13.821 | Z11: 49.538 | AB11: 752.323 | AC11: 39.48 | AD11: -14.806 | AE11: 40.124 | AG11: 817.121 | AH11: 39.347 | AI11: -15.407 | AJ11: 30.75 | AL11: 871.811 | AM11: 41.086 | AN11: -16.051 | AO11: 31.606 | AQ11: 928.451 | AR11: 43.994 | AS11: -16.924 | AT11: 35.615 | AV11: 991.136 | AW11: 48.297 | AX11: -18.163 | AY11: 33.96 | BA11: 1055.23 | BB11: 53.761 | BC11: -19.588 | BD11: 35.479 | BF11: 1124.882 | BG11: 55.053 | BH11: -21.33 | BI11: 46.635 | BK11: 1205.24 | BL11: 53.502 | BM11: -23.018 | BN11: 34.546 | BP11: 1270.27 | BQ11: 51.402 | BR11: -23.827 | BS11: 16.669 | BU11: 1314.513 | BV11: 49.524 | BW11: -24.377 | BX11: 12.868 | BZ11: 1352.529 | CA11: 51.897 | CB11: -24.828 | CC11: 10.35 | CE11: 1389.948 | CF11: 52.777 | CG11: -24.787 | CH11: 20.682 | CJ11: 1438.619 | CK11: 53.695 | CL11: -25.166 | CM11: 29.275 | CO11: 1496.424 | CP11: 56.946 | CQ11: -26.156 | CR11: 22.687 | CT11: 1549.9 | CU11: 60.377 | CV11: -26.99 | CW11: 12.328 | CY11: 1595.614 | CZ11: 65.475 | DA11: -27.845 | DB11: 14.252 | DD11: 1647.497 | DE11: 68.763 | DF11: -29.062 | DG11: 36.331 | DI11: 1723.53 | DJ11: 71.611 | DK11: -30.819 | DL11: 54.079 | DN11: 1818.4 | DO11: 75.751 | DP11: -32.661 | DQ11: 53.257 | DS11: 1914.747 | DT11: 80.187 | DU11: -34.692 | DV11: 73.968 | DX11: 2034.21 | DY11: 87.899 | DZ11: -37.649 | EA11: 90.355 | EC11: 2174.815 | ED11: 95.314 | EE11: -40.516 | EF11: 87.546 | EH11: 2317.159 | EI11: 106.175 | EJ11: -44.149 | EK11: 93.405 | EM11: 2472.589 | EN11: 113.479 | EO11: -47.751 | EP11: 106.654 | ER11: 2644.971 | ES11: 115.823 | ET11: -51.806 | EU11: 67.266 | EW11: 2776.254 | EX11: 100.362 | EY11: -51.42 | EZ11: 30.138 | FB11: 2855.334 | FC11: 103.585 | FD11: -53.4 | FE11: 61.667 | FG11: 2967.187 | FH11: 108.322 | FI11: -55.213 | FJ11: 62.678 | FL11: 3082.974 | FM11: 107.719 | FN11: -55.95 | FO11: 28.315 | FQ11: 3163.058 | FR11: 106.909 | FS11: -56.121 | FT11: 31.408 | FV11: 3245.254 | FW11: 105.986 | FX11: -58.061 | FY11: 26.721 | GA11: 3319.9 | GB11: 104.814 | GC11: -59.12 | GD11: 4.01 | GF11: 3369.604 | GG11: 108.142 | GH11: -60.07 | GI11: 36.853 | GK11: 3454.529 | GL11: 116.718 | GM11: -63.013 | GN11: 60.094 | GP11: 3568.328 | GQ11: 121.034 | GR11: -66.166 | GS11: 64.662 | GU11: 3687.858 | GV11: 127.185 | GW11: -70.058 | GX11: 52.36 | GZ11: 3797.345 | HA11: 120.183 | HB11: -73.68 | HC11: 104.234 | HE11: 3948.081 | HF11: 144.722 | HG11: -79.677 | HH11: 271.706 | HJ11: 4284.832 | HK11: 151.887 | HL11: -87.918 | HM11: 264.647 | HO11: 4613.448 | HP11: 143.032 | HQ11: -90.214 | HR11: 86.422 | HT11: 4752.687 | HU11: 134.912 | HV11: -89.115 | HW11: 8.927 | HY11: 4807.411
A12: N112 | B12: Autres bâtiments et ouvrages de génie civil | C12: 44.341 | D12: 2.589 | E12: -2.532 | F12: 7.184 | H12: 51.582 | I12: 2.981 | J12: -2.981 | K12: 8.134 | M12: 59.716 | N12: 3.156 | O12: -3.361 | P12: 8.063 | R12: 67.572 | S12: 3.334 | T12: -3.803 | U12: 7.734 | W12: 74.839 | X12: 3.44 | Y12: -4.118 | Z12: 6.028 | AB12: 80.188 | AC12: 3.611 | AD12: -4.388 | AE12: 4.415 | AG12: 83.825 | AH12: 3.467 | AI12: -4.542 | AJ12: 3.23 | AL12: 85.98 | AM12: 3.779 | AN12: -4.677 | AO12: 3.647 | AQ12: 88.728 | AR12: 4.146 | AS12: -4.856 | AT12: 4.484 | AV12: 92.501 | AW12: 4.376 | AX12: -5.078 | AY12: 4.838 | BA12: 96.636 | BB12: 4.854 | BC12: -5.297 | BD12: 4.051 | BF12: 100.244 | BG12: 4.541 | BH12: -5.432 | BI12: 2.959 | BK12: 102.313 | BL12: 4.348 | BM12: -5.56 | BN12: 1.267 | BP12: 102.368 | BQ12: 4.408 | BR12: -5.538 | BS12: -0.104 | BU12: 101.133 | BV12: 4.216 | BW12: -5.482 | BX12: 0.952 | BZ12: 100.819 | CA12: 4.394 | CB12: -5.519 | CC12: 1.853 | CE12: 101.546 | CF12: 4.406 | CG12: -5.543 | CH12: 1.8 | CJ12: 102.21 | CK12: 4.104 | CL12: -5.572 | CM12: 2.814 | CO12: 103.555 | CP12: 4.265 | CQ12: -5.689 | CR12: 3.408 | CT12: 105.539 | CU12: 4.626 | CV12: -5.83 | CW12: 3.587 | CY12: 107.922 | CZ12: 5.242 | DA12: -5.995 | DB12: 4.663 | DD12: 111.832 | DE12: 5.069 | DF12: -6.263 | DG12: 3.661 | DI12: 114.298 | DJ12: 5.148 | DK12: -6.36 | DL12: 2.415 | DN12: 115.499 | DO12: 5.359 | DP12: -6.456 | DQ12: 3.711 | DS12: 118.113 | DT12: 5.491 | DU12: -6.607 | DV12: 4.333 | DX12: 121.331 | DY12: 5.56 | DZ12: -6.749 | EA12: 4.205 | EC12: 124.347 | ED12: 5.696 | EE12: -6.904 | EF12: 4.508 | EH12: 127.646 | EI12: 5.969 | EJ12: -7.087 | EK12: 4.909 | EM12: 131.435 | EN12: 6.507 | EO12: -7.337 | EP12: 6.162 | ER12: 136.766 | ES12: 7.049 | ET12: -7.735 | EU12: 4.106 | EW12: 140.184 | EX12: 6.374 | EY12: -7.802 | EZ12: 3.615 | FB12: 142.37 | FC12: 6.821 | FD12: -8.015 | FE12: 6.355 | FG12: 147.53 | FH12: 6.782 | FI12: -8.279 | FJ12: 5.316 | FL12: 151.347 | FM12: 6.921 | FN12: -8.453 | FO12: 2.314 | FQ12: 152.127 | FR12: 7.376 | FS12: -8.439 | FT12: -0.246 | FV12: 150.818 | FW12: 7.652 | FX12: -8.405 | FY12: -2.705 | GA12: 147.357 | GB12: 8.019 | GC12: -8.338 | GD12: -2.681 | GF12: 144.356 | GG12: 8.991 | GH12: -8.523 | GI12: 0.965 | GK12: 145.785 | GL12: 9.603 | GM12: -8.849 | GN12: 3.318 | GP12: 149.856 | GQ12: 10.557 | GR12: -9.305 | GS12: 3.091 | GU12: 154.197 | GV12: 11.613 | GW12: -9.805 | GX12: 1.23 | GZ12: 157.232 | HA12: 12.054 | HB12: -10.202 | HC12: 3.378 | HE12: 162.459 | HF12: 12.824 | HG12: -10.852 | HH12: 12.015 | HJ12: 176.444 | HK12: 12.188 | HL12: -11.817 | HM12: 11.939 | HO12: 188.756 | HP12: 11.811 | HQ12: -12.255 | HR12: 4.13 | HT12: 192.444 | HU12: 11.622 | HV12: -12.334 | HW12: 2.006 | HY12: 193.738
A13: N1121 | B13: Bâtiments non résidentiels | C13: 20.119 | D13: 1.623 | E13: -1.748 | F13: 2.589 | H13: 22.581 | I13: 1.865 | J13: -2.021 | K13: 2.989 | M13: 25.415 | N13: 1.962 | O13: -2.256 | P13: 2.98 | R13: 28.102 | S13: 2.076 | T13: -2.518 | U13: 2.798 | W13: 30.458 | X13: 2.133 | Y13: -2.703 | Z13: 2.198 | AB13: 32.086 | AC13: 2.254 | AD13: -2.86 | AE13: 1.743 | AG13: 33.223 | AH13: 2.122 | AI13: -2.956 | AJ13: 1.116 | AL13: 33.504 | AM13: 2.358 | AN13: -3.009 | AO13: 0.876 | AQ13: 33.729 | AR13: 2.619 | AS13: -3.088 | AT13: 1.015 | AV13: 34.274 | AW13: 2.725 | AX13: -3.182 | AY13: 0.935 | BA13: 34.752 | BB13: 3.039 | BC13: -3.271 | BD13: 0.799 | BF13: 35.318 | BG13: 2.732 | BH13: -3.321 | BI13: 1.029 | BK13: 35.758 | BL13: 2.65 | BM13: -3.409 | BN13: 0.84 | BP13: 35.838 | BQ13: 2.724 | BR13: -3.403 | BS13: 0.323 | BU13: 35.482 | BV13: 2.561 | BW13: -3.364 | BX13: 0.183 | BZ13: 34.863 | CA13: 2.652 | CB13: -3.338 | CC13: 0.099 | CE13: 34.275 | CF13: 2.666 | CG13: -3.314 | CH13: 0.168 | CJ13: 33.796 | CK13: 2.466 | CL13: -3.294 | CM13: 0.363 | CO13: 33.331 | CP13: 2.531 | CQ13: -3.311 | CR13: 0.643 | CT13: 33.195 | CU13: 2.776 | CV13: -3.382 | CW13: 0.61 | CY13: 33.199 | CZ13: 3.136 | DA13: -3.428 | DB13: 1.146 | DD13: 34.054 | DE13: 2.92 | DF13: -3.593 | DG13: 1.548 | DI13: 34.928 | DJ13: 2.962 | DK13: -3.669 | DL13: 0.903 | DN13: 35.124 | DO13: 3.067 | DP13: -3.7 | DQ13: 0.718 | DS13: 35.209 | DT13: 3.058 | DU13: -3.727 | DV13: 0.959 | DX13: 35.499 | DY13: 2.946 | DZ13: -3.78 | EA13: 1.182 | EC13: 35.846 | ED13: 2.922 | EE13: -3.833 | EF13: 1.118 | EH13: 36.053 | EI13: 3.004 | EJ13: -3.901 | EK13: 1.164 | EM13: 36.319 | EN13: 3.348 | EO13: -4.022 | EP13: 1.371 | ER13: 37.016 | ES13: 3.771 | ET13: -4.231 | EU13: 1.073 | EW13: 37.629 | EX13: 3.409 | EY13: -4.304 | EZ13: 0.489 | FB13: 37.224 | FC13: 3.472 | FD13: -4.317 | FE13: 0.621 | FG13: 37 | FH13: 3.491 | FI13: -4.413 | FJ13: 0.908 | FL13: 36.985 | FM13: 3.679 | FN13: -4.49 | FO13: 0.363 | FQ13: 36.538 | FR13: 3.835 | FS13: -4.473 | FT13: -0.079 | FV13: 35.82 | FW13: 3.968 | FX13: -4.479 | FY13: -0.129 | GA13: 35.18 | GB13: 4.382 | GC13: -4.569 | GD13: -0.207 | GF13: 34.785 | GG13: 5.183 | GH13: -4.784 | GI13: -0.095 | GK13: 35.089 | GL13: 5.415 | GM13: -5.01 | GN13: 0.335 | GP13: 35.828 | GQ13: 6.046 | GR13: -5.353 | GS13: 0.49 | GU13: 37.011 | GV13: 6.838 | GW13: -5.773 | GX13: 0.257 | GZ13: 38.332 | HA13: 7.373 | HB13: -6.167 | HC13: 0.675 | HE13: 40.212 | HF13: 7.511 | HG13: -6.609 | HH13: 2.117 | HJ13: 43.232 | HK13: 7.134 | HL13: -7.088 | HM13: 2.315 | HO13: 45.595 | HP13: 6.823 | HQ13: -7.379 | HR13: 1.123 | HT13: 46.162 | HU13: 6.667 | HV13: -7.409 | HW13: 0.496 | HY13: 45.917
A14: N1122 | B14: Autres ouvrages de génie civil | C14: 24.223 | D14: 0.966 | E14: -0.783 | F14: 4.595 | H14: 29.001 | I14: 1.115 | J14: -0.96 | K14: 5.145 | M14: 34.301 | N14: 1.193 | O14: -1.106 | P14: 5.082 | R14: 39.471 | S14: 1.258 | T14: -1.284 | U14: 4.936 | W14: 44.381 | X14: 1.307 | Y14: -1.415 | Z14: 3.83 | AB14: 48.103 | AC14: 1.356 | AD14: -1.529 | AE14: 2.673 | AG14: 50.603 | AH14: 1.345 | AI14: -1.587 | AJ14: 2.115 | AL14: 52.476 | AM14: 1.421 | AN14: -1.668 | AO14: 2.771 | AQ14: 54.999 | AR14: 1.527 | AS14: -1.769 | AT14: 3.469 | AV14: 58.227 | AW14: 1.651 | AX14: -1.896 | AY14: 3.903 | BA14: 61.885 | BB14: 1.816 | BC14: -2.026 | BD14: 3.252 | BF14: 64.926 | BG14: 1.809 | BH14: -2.111 | BI14: 1.93 | BK14: 66.555 | BL14: 1.699 | BM14: -2.151 | BN14: 0.427 | BP14: 66.529 | BQ14: 1.685 | BR14: -2.135 | BS14: -0.428 | BU14: 65.651 | BV14: 1.655 | BW14: -2.119 | BX14: 0.769 | BZ14: 65.956 | CA14: 1.742 | CB14: -2.181 | CC14: 1.754 | CE14: 67.271 | CF14: 1.74 | CG14: -2.229 | CH14: 1.632 | CJ14: 68.414 | CK14: 1.638 | CL14: -2.278 | CM14: 2.451 | CO14: 70.224 | CP14: 1.733 | CQ14: -2.379 | CR14: 2.765 | CT14: 72.344 | CU14: 1.85 | CV14: -2.448 | CW14: 2.978 | CY14: 74.723 | CZ14: 2.105 | DA14: -2.568 | DB14: 3.517 | DD14: 77.778 | DE14: 2.149 | DF14: -2.67 | DG14: 2.113 | DI14: 79.37 | DJ14: 2.186 | DK14: -2.691 | DL14: 1.512 | DN14: 80.376 | DO14: 2.292 | DP14: -2.756 | DQ14: 2.993 | DS14: 82.904 | DT14: 2.433 | DU14: -2.879 | DV14: 3.374 | DX14: 85.832 | DY14: 2.614 | DZ14: -2.969 | EA14: 3.023 | EC14: 88.5 | ED14: 2.774 | EE14: -3.071 | EF14: 3.39 | EH14: 91.593 | EI14: 2.965 | EJ14: -3.187 | EK14: 3.746 | EM14: 95.116 | EN14: 3.158 | EO14: -3.316 | EP14: 4.79 | ER14: 99.749 | ES14: 3.278 | ET14: -3.504 | EU14: 3.033 | EW14: 102.555 | EX14: 2.965 | EY14: -3.499 | EZ14: 3.126 | FB14: 105.146 | FC14: 3.348 | FD14: -3.698 | FE14: 5.734 | FG14: 110.53 | FH14: 3.291 | FI14: -3.867 | FJ14: 4.408 | FL14: 114.362 | FM14: 3.242 | FN14: -3.964 | FO14: 1.951 | FQ14: 115.59 | FR14: 3.541 | FS14: -3.966 | FT14: -0.167 | FV14: 114.997 | FW14: 3.684 | FX14: -3.926 | FY14: -2.577 | GA14: 112.177 | GB14: 3.637 | GC14: -3.769 | GD14: -2.474 | GF14: 109.571 | GG14: 3.808 | GH14: -3.74 | GI14: 1.059 | GK14: 110.697 | GL14: 4.188 | GM14: -3.839 | GN14: 2.983 | GP14: 114.027 | GQ14: 4.512 | GR14: -3.953 | GS14: 2.601 | GU14: 117.186 | GV14: 4.775 | GW14: -4.032 | GX14: 0.973 | GZ14: 118.901 | HA14: 4.681 | HB14: -4.035 | HC14: 2.703 | HE14: 122.246 | HF14: 5.313 | HG14: -4.243 | HH14: 9.898 | HJ14: 133.212 | HK14: 5.054 | HL14: -4.729 | HM14: 9.623 | HO14: 143.161 | HP14: 4.989 | HQ14: -4.876 | HR14: 3.006 | HT14: 146.281 | HU14: 4.954 | HV14: -4.925 | HW14: 1.51 | HY14: 147.821
